Workbook

Sheet 癌
A1: 姓名 | B1: 年龄 | C1: 病理 | F1: 编号 | G1: 编号2 | H1: sampleID | I1: type
A2: 王阿素 | B2: 64 | C2: 高级别浆液性癌IIIc期 | F2: B51 | G2: P1 | H2: ov1 | I2: =VLOOKUP(A2,训练集亚型!$A$1:$F$1000,4,0) -> a
A3: 徐燕萍 | B3: 71 | C3: 高级别浆液性癌IIIb期 | F3: B2 | G3: P2 | H3: ov2 | I3: =VLOOKUP(A3,训练集亚型!$A$1:$F$1000,4,0) -> a
A4: 周明莉 | B4: 56 | C4: 高级别浆液性癌，复发 | F4: B12 | G4: P3 | H4: ov3 | I4: =VLOOKUP(A4,训练集亚型!$A$1:$F$1000,4,0) -> a
A5: 张东荣 | B5: 49 | C5: 高级别浆液性癌IIIc期 | F5: B3 | G5: P4 | H5: ov4 | I5: =VLOOKUP(A5,训练集亚型!$A$1:$F$1000,4,0) -> a
A6: 韩玉凤 | B6: 66 | C6: 高级别浆液性癌IIIc期 | G6: P7 | H6: ov7 | I6: =VLOOKUP(A6,训练集亚型!$A$1:$F$1000,4,0) -> a
A7: 孔彩香 | B7: 56 | C7: 高级别浆液性癌IIIc期 | F7: B8 | G7: P9 | H7: ov8 | I7: =VLOOKUP(A7,训练集亚型!$A$1:$F$1000,4,0) -> a
A8: 陈菊华 | B8: 50 | C8: 高级别浆液性癌IIIA | F8: B15 | G8: P12 | H8: ov10 | I8: =VLOOKUP(A8,训练集亚型!$A$1:$F$1000,4,0) -> a
A9: 刘民族 | B9: 50 | C9: 低级别合并高级别浆液性癌IIIA1 | F9: B18 | G9: P13 | H9: ov11 | I9: =VLOOKUP(A9,训练集亚型!$A$1:$F$1000,4,0) -> a
A10: 王妙芬 | B10: 61 | C10: 高级别浆液性癌IV期 | F10: B20 | G10: P14 | H10: ov12 | I10: =VLOOKUP(A10,训练集亚型!$A$1:$F$1000,4,0) -> a
A11: 吴明英 | B11: 45 | C11: 卵巢高级别浆液性癌IIIC期，G3 | F11: B55 | G11: P15 | H11: ov13 | I11: =VLOOKUP(A11,训练集亚型!$A$1:$F$1000,4,0) -> a
A12: 曾琴妹 | B12: 47 | C12: 卵巢恶性肿瘤IIb期（高级别浆液性癌）（G3），肠粘连 | F12: B21 | G12: P17 | H12: ov15 | I12: =VLOOKUP(A12,训练集亚型!$A$1:$F$1000,4,0) -> a
A13: 潘珠凤 | B13: 66 | C13: 晚期卵巢浆液性恶性肿瘤（新辅助化疗后），高血压病，胆囊结石，肠粘连 | F13: B45 | G13: P19 | H13: ov17 | I13: =VLOOKUP(A13,训练集亚型!$A$1:$F$1000,4,0) -> a
A14: 俞一莉 | B14: 63 | C14: 双侧卵巢恶性肿瘤（高级别浆液性癌）IIB期，子宫多发性平滑肌瘤，盆腔肿块（纤维脂肪组织），支气管哮喘，真菌性阴道炎（已治愈），中度贫血，尿潴留 | F14: B67 | G14: P20 | H14: ov18 | I14: =VLOOKUP(A14,训练集亚型!$A$1:$F$1000,4,0) -> a
A15: 蓝惠仙 | B15: 42 | C15: 卵巢恶性肿瘤IIIC期（浆液性癌G3），中度贫血，肠粘连，子宫肌瘤，疤痕子宫，肝功能异常（已治愈） | F15: B68 | G15: P21 | H15: ov19 | I15: =VLOOKUP(A15,训练集亚型!$A$1:$F$1000,4,0) -> a
A16: 胡夏娅 | B16: 55 | C16: 卵巢恶性肿瘤（高级别浆液性癌IIIC期）术后复发，肠粘连，轻度贫血，甲状腺癌切除个人史 | F16: B85 | G16: P22 | H16: ov20 | I16: =VLOOKUP(A16,训练集亚型!$A$1:$F$1000,4,0) -> a
A17: 周亚君 | B17: 67 | C17: 卵巢恶性肿瘤（浆液性癌IIIC期），肠粘连，轻度贫血 | F17: B69 | G17: P23 | H17: ov21 | I17: =VLOOKUP(A17,训练集亚型!$A$1:$F$1000,4,0) -> a
A18: 潘微明 | B18: 51 | C18: 双卵巢恶性肿瘤（高级别浆液性癌）IIIC期，子宫多发性平滑肌瘤（其一为宫颈肌瘤），肠粘连，输尿管周围粘连，轻度贫血 | F18: B76 | G18: P24 | H18: ov22 | I18: =VLOOKUP(A18,训练集亚型!$A$1:$F$1000,4,0) -> a
A19: 张珍 | B19: 42 | C19: 卵巢高级别浆液性癌IIIC | G19: P25 | H19: ov23 | I19: =VLOOKUP(A19,训练集亚型!$A$1:$F$1000,4,0) -> a
A20: 吕彩芹 | B20: 69 | C20: 右卵巢恶性肿瘤IIIC期 | G20: P26 | H20: ov24 | I20: =VLOOKUP(A20,训练集亚型!$A$1:$F$1000,4,0) -> a
A21: 周小珍 | B21: 48 | C21: 双卵巢高级别浆液性癌IIIc期，CINIII | G21: P27 | H21: ov25 | I21: =VLOOKUP(A21,训练集亚型!$A$1:$F$1000,4,0) -> a
A22: 严瑶芬 | B22: 60 | C22: 浆液性腺癌IV晚期，远处大量转移，未手术 | F22: B47 | H22: ov30 | I22: =VLOOKUP(A22,训练集亚型!$A$1:$F$1000,4,0) -> a
A23: 张红琴 | B23: 44 | C23: 卵巢恶性肿瘤（卵巢高级别浆液性癌IIIc期）术后 | F23: B26 | H23: ov35 | I23: =VLOOKUP(A23,训练集亚型!$A$1:$F$1000,4,0) -> a
A24: 瞿春红 | B24: 51 | C24: 复发性卵巢恶性肿瘤，卵巢恶性肿瘤（高级别浆液性腺癌IIIc期）术后，乳腺癌术后，轻度贫血 | F24: B29 | H24: ov38 | I24: =VLOOKUP(A24,训练集亚型!$A$1:$F$1000,4,0) -> a
A25: 俞美群 | B25: 63 | C25: 卵巢恶性肿瘤（高级别浆液性癌）IV期，腹壁肿物（纤维组织伴钙化），肠粘连 | F25: B31 | H25: ov40 | I25: =VLOOKUP(A25,训练集亚型!$A$1:$F$1000,4,0) -> a
A26: 沈玲飞 | B26: 54 | C26: 高级别浆液性腺癌Iic期 | F26: B32 | H26: ov41 | I26: =VLOOKUP(A26,训练集亚型!$A$1:$F$1000,4,0) -> a
A27: 董英娣 | B27: 65 | C27: 卵巢恶性肿瘤IIA（高级别浆液性癌）术后化疗，轻度贫血 | F27: B59 | H27: ov44 | I27: =VLOOKUP(A27,训练集亚型!$A$1:$F$1000,4,0) -> a
A28: 任爱珍 | B28: 68 | C28: 双侧卵巢输卵管恶性肿瘤IIIC期（G3）术后化疗 | F28: B63 | H28: ov48 | I28: =VLOOKUP(A28,训练集亚型!$A$1:$F$1000,4,0) -> a
A29: 卓美玲 | B29: 63 | C29: 卵巢恶性肿瘤（右侧卵巢高级别浆液性癌ⅢC期），子宫切除术后状态（次切术后），肝脏多发囊肿 | F29: B64 | H29: ov49 | I29: =VLOOKUP(A29,训练集亚型!$A$1:$F$1000,4,0) -> a
A30: 陈彩娥 | B30: 51 | C30: 复发性卵巢恶性肿瘤，卵巢浆液性腺癌IIIC期术后，肠粘连，药物性肝损害 | F30: B73 | H30: ov54 | I30: =VLOOKUP(A30,训练集亚型!$A$1:$F$1000,4,0) -> a
A31: 周丽丽 | B31: 64 | C31: 双卵巢恶性肿瘤（高级别浆液性癌）IIIC期，子宫腺肌病，肠粘连，输尿管周围粘连，肝功能异常 | F31: B75 | H31: ov56 | I31: =VLOOKUP(A31,训练集亚型!$A$1:$F$1000,4,0) -> a
A32: 马桂贞 | B32: 63 | C32: 左侧卵巢高级别浆液性癌IIIC期（G3），慢性肾盂肾炎，轻度贫血 | F32: B79 | H32: ov58 | I32: =VLOOKUP(A32,训练集亚型!$A$1:$F$1000,4,0) -> a
A33: 李月青 | B33: 65 | C33: 卵巢恶性肿瘤IIIC期（高级别浆液性癌，局部透明细胞癌），高血压，胸腔积液，肠粘连，中度贫血 | F33: B81 | H33: ov60 | I33: =VLOOKUP(A33,训练集亚型!$A$1:$F$1000,4,0) -> a
... A64: 杨增兰 | B64: 60 | C64: 卵巢恶性肿瘤IIIC期（高级别浆液性癌） | F64: B153 | H64: ov114 | I64: =VLOOKUP(A64,训练集亚型!$A$1:$F$1000,4,0) -> a
A65: 姜如香 | B65: 63 | C65: 左输卵管高级别浆液性癌IIIC | G65: P29 | H65: ov27 | I65: =VLOOKUP(A65,训练集亚型!$A$1:$F$1000,4,0) -> b
A66: 王小英 | B66: 51 | C66: 右输卵管高级别浆液性癌IIIC期 | F66: B105 | H66: ov75 | I66: =VLOOKUP(A66,训练集亚型!$A$1:$F$1000,4,0) -> b
A67: 尹招娟 | B67: 71 | C67: 双侧输卵管高级别浆液性癌IIIC期 | F67: B125 | H67: ov86 | I67: =VLOOKUP(A67,训练集亚型!$A$1:$F$1000,4,0) -> b
A68: 单静芳 | B68: 56 | C68: 左侧输卵管恶性肿瘤IIIC期（浆液性G3） | F68: B143 | H68: ov104 | I68: =VLOOKUP(A68,训练集亚型!$A$1:$F$1000,4,0) -> b
A69: 张秋月 | B69: 75 | C69: 左输卵管恶性肿瘤IIIA1（i）期（浆液性癌，G3） | F69: B154 | H69: ov108 | I69: =VLOOKUP(A69,训练集亚型!$A$1:$F$1000,4,0) -> b
A70: 王璐莹 | B70: 14 | C70: 右卵巢混合性生殖细胞肿瘤IC1期（卵黄囊瘤+成熟性畸胎瘤） | F70: B58 | H70: ov28 | I70: =VLOOKUP(A70,训练集亚型!$A$1:$F$1000,4,0) -> c
...

Sheet 训练集亚型
A1: Sample | B1: age | C1: type | D1: type1
A2: 王阿素 | B2: 64 | C2: 高级别浆液性卵巢癌 | D2: a
A3: 徐燕萍 | B3: 71 | C3: 高级别浆液性卵巢癌 | D3: a
A4: 周明莉 | B4: 56 | C4: 高级别浆液性卵巢癌 | D4: a
A5: 张东荣 | B5: 49 | C5: 高级别浆液性卵巢癌 | D5: a
A6: 韩玉凤 | B6: 66 | C6: 高级别浆液性卵巢癌 | D6: a
A7: 孔彩香 | B7: 56 | C7: 高级别浆液性卵巢癌 | D7: a
A8: 陈菊华 | B8: 50 | C8: 高级别浆液性卵巢癌 | D8: a
A9: 刘民族 | B9: 50 | C9: 高级别浆液性卵巢癌 | D9: a
A10: 王妙芬 | B10: 61 | C10: 高级别浆液性卵巢癌 | D10: a
A11: 吴明英 | B11: 45 | C11: 高级别浆液性卵巢癌 | D11: a
A12: 曾琴妹 | B12: 47 | C12: 高级别浆液性卵巢癌 | D12: a
A13: 俞一莉 | B13: 63 | C13: 高级别浆液性卵巢癌 | D13: a
... A115: 丁水德 | B115: 69 | C115: 腹膜癌 | D115: k

Sheet 囊肿
A1: 组别 | B1: 姓名 | C1: 年龄 | D1: 编号 | E1: 备注 | F1: sampleID
A2: 囊腺瘤 | B2: 刘冰如 | C2: 57 | D2: a95 | F2: cys1
A3: 囊腺瘤 | B3: 刘湘 | C3: 39 | D3: a56 | F3: cys2
A4: 囊腺瘤 | B4: 黄婷婷 | C4: 35 | D4: a54 | F4: cys3
A5: 囊腺瘤 | B5: 王丽芬 | C5: 49 | D5: a32 | F5: cys4
A6: 囊腺瘤 | B6: 林芝英 | C6: 77 | D6: a34 | F6: cys5
A7: 囊腺瘤 | B7: 程卫东 | C7: 50 | D7: a105 | F7: cys6
A8: 囊腺瘤 | B8: 陈瑾 | C8: 40 | D8: a133 | F8: cys7
A9: 囊腺瘤 | B9: 张国华 | C9: 63 | D9: a143 | F9: cys8
A10: 囊腺瘤 | B10: 戴国凤 | C10: 50 | D10: a178 | F10: cys9
A11: 内异 | B11: 李宁 | C11: 40 | D11: a81 | F11: cys10
A12: 内异 | B12: 黄玥 | C12: 33 | D12: a195 | F12: cys11
A13: 内异 | B13: 尹娟娟 | C13: 40 | D13: a79 | F13: cys12
... A37: 内异 | B37: 王文英 | C37: 48 | D37: a31 | F37: cys36
A38: 内异 | B38: 黄玥 | C38: 33 | D38: a33 | E38: 与a195为同病人，此次为术后复发 | F38: cys37
A39: 内异 | B39: 沈建林 | C39: 53 | D39: a37 | F39: cys38
A40: 内异 | B40: 余锟晴 | C40: 24 | D40: a39 | F40: cys39
A41: 内异 | B41: 缪慧波 | C41: 41 | D41: a41 | F41: cys40
A42: 内异 | B42: 冯敏 | C42: 35 | D42: a42 | F42: cys41
A43: 内异 | B43: 王雁 | C43: 52 | D43: a20 | F43: cys42
A44: 内异 | B44: 沈玉萍 | C44: 41 | D44: a121 | F44: cys43
A45: 内异 | B45: 余意平 | C45: 44 | D45: a122 | F45: cys44
A46: 内异 | B46: 杨燕飞 | C46: 40 | D46: a127 | F46: cys45
A47: 内异 | B47: 傅瑶平 | C47: 35 | D47: a128 | F47: cys46
A48: 内异 | B48: 金萍 | C48: 20 | D48: a129 | F48: cys47
A49: 内异 | B49: 马路 | C49: 33 | D49: a69 | F49: cys48
A50: 内异 | B50: 谢华 | C50: 46 | D50: a78 | F50: cys49
... A57: 内异 | B57: 卢素梅 | C57: 46 | D57: a125 | F57: cys56
A58: 内异 | B58: 赵洁 | C58: 36 | D58: a97 | E58: 原a97还没换 | F58: cys57
A59: 内异 | B59: 商洪柳 | C59: 30 | D59: a193 | F59: cys58
A60: 内异 | B60: 吴春岚 | C60: 21 | D60: a1 | F60: cys59
A61: 内异 | B61: 侯明应 | C61: 36 | D61: a104 | F61: cys60
A62: 内异 | B62: 车渝妙 | C62: 47 | D62: a112 | F62: cys61
A63: 内异 | B63: 潘之嫣 | C63: 26 | D63: a132 | F63: cys62
A64: 内异 | B64: 吴兰聪 | C64: 27 | D64: a134 | F64: cys63
A65: 内异 | B65: 杜侃宁 | C65: 23 | D65: a135 | F65: cys64
A66: 内异 | B66: 马燕芬 | C66: 32 | D66: a137 | F66: cys65
A67: 内异 | B67: 林滨滨 | C67: 27 | D67: a138 | F67: cys66
A68: 内异 | B68: 卢双双 | C68: 33 | D68: a141 | F68: cys67
A69: 内异 | B69: 毛世艳 | C69: 37 | D69: a142 | F69: cys68
...

Sheet 健康
A1: 旧编号 | B1: 住院号 | C1: 姓名 | D1: 性别 | E1: 年龄 | F1: 乙肝 | G1: afp | H1: ast（15-40） | I1: alt（7-50） | J1: 新编号 | L1: sampleID
A2: 2 | B2: 20325286 | C2: 吴红 | D2: 女 | E2: 43 | F2: 未查 | G2: 3.3 | H2: 13 | I2: 22 | J2: c1 | L2: ctrl1
A3: 4 | B3: 20374776 | C3: 汤美伟 | D3: 女 | E3: 27 | F3: 未查 | G3: 2.9 | H3: 20 | I3: 11 | J3: c2 | L3: ctrl2
A4: 6 | B4: 20375385 | C4: 钟燕楠 | D4: 女 | E4: 22 | F4: 未查 | H4: 12 | I4: 7 | J4: c3 | L4: ctrl3
A5: 7 | B5: 20325220 | C5: 武茜 | D5: 女 | E5: 42 | F5: 未查 | G5: 2 | H5: 17 | I5: 15 | J5: c4 | L5: ctrl4
A6: 8 | B6: 20374716 | C6: 高洁华 | D6: 女 | E6: 35 | F6: 未查 | H6: 20 | I6: 32 | J6: c5 | L6: ctrl5
A7: 10 | B7: 20374647 | C7: 蔡俏英 | D7: 女 | E7: 34 | F7: 未查 | H7: 23 | I7: 14 | J7: c6 | L7: ctrl6
A8: 12 | B8: 20374670 | C8: 胡珏 | D8: 女 | E8: 40 | F8: 未查 | H8: 16 | I8: 9 | J8: c7 | L8: ctrl7
A9: 14 | B9: 20374937 | C9: 陆羽婕 | D9: 女 | E9: 27 | F9: 未查 | H9: 17 | I9: 10 | J9: c8 | L9: ctrl8
A10: 16 | B10: 20360372 | C10: 吴凡 | D10: 女 | E10: 29 | F10: 未查 | G10: 1.8 | H10: 15 | I10: 9 | J10: c9 | L10: ctrl9
A11: 17 | B11: 20375250 | C11: 陈梦瑶 | D11: 女 | E11: 23 | F11: 未查 | G11: 2.5 | H11: 13 | I11: 7 | J11: c10 | L11: ctrl10
A12: 19 | B12: 20375034 | C12: 莫嘉 | D12: 女 | E12: 25 | F12: 未查 | G12: 0.7 | H12: 22 | I12: 45 | J12: c11 | L12: ctrl11
A13: 22 | B13: 20365155 | C13: 陈正洋 | D13: 女 | E13: 31 | F13: 未查 | G13: 1.2 | H13: 13 | I13: 18 | J13: c12 | L13: ctrl12
A14: 23 | B14: 20325306 | C14: 阮春英 | D14: 女 | E14: 51 | F14: 未查 | G14: 6.9 | H14: 15 | I14: 10 | J14: c13 | L14: ctrl13
A15: 25 | B15: 20363121 | C15: 闫慧子 | D15: 女 | E15: 33 | F15: 未查 | G15: 2.6 | H15: 11 | I15: 7 | J15: c14 | L15: ctrl14
A16: 26 | B16: 20325281 | C16: 林雪芬 | D16: 女 | E16: 40 | F16: 未查 | G16: 2.1 | H16: 23 | I16: 21 | J16: c15 | L16: ctrl15
A17: 28 | B17: 20282447 | C17: 黄冰群 | D17: 女 | E17: 49 | F17: 未查 | G17: 5.8 | H17: 32 | I17: 34 | J17: c16 | L17: ctrl16
A18: 30 | B18: 20324270 | C18: 雷艳铃 | D18: 女 | E18: 45 | F18: 未查 | J18: c17 | L18: ctrl17
A19: 31 | B19: 20874444 | C19: 任少凡 | D19: 女 | E19: 28 | F19: 未查 | G19: 1.3 | H19: 16 | I19: 11 | J19: c18 | L19: ctrl18
A20: 35 | B20: 20374549 | C20: 马玉静 | D20: 女 | E20: 28 | F20: 未查 | G20: 3 | H20: 21 | I20: 17 | J20: c19 | L20: ctrl19
A21: 36 | B21: 20374302 | C21: 虎陈霞 | D21: 女 | E21: 41 | F21: 未查 | G21: 2 | H21: 22 | I21: 18 | J21: c20 | L21: ctrl20
A22: 38 | B22: 20374624 | C22: 曹吉莉 | D22: 女 | E22: 32 | F22: 未查 | I22: 15 | J22: c21 | L22: ctrl21
A23: 40 | B23: 20365111 | C23: 李致颖 | D23: 女 | E23: 29 | F23: 未查 | G23: 2.5 | H23: 14 | I23: 11 | J23: c22 | L23: ctrl22
A24: 46 | B24: 20375483 | C24: 王玉婷 | D24: 女 | E24: 22 | F24: 未查 | H24: 12 | I24: 8 | J24: c23 | L24: ctrl23
A25: 49 | B25: 20379600 | C25: 徐晖 | D25: 女 | E25: 51 | F25: 未查 | G25: 1.5 | H25: 23 | I25: 19 | J25: c24 | L25: ctrl24
A26: 50 | B26: 20325685 | C26: 许芳 | D26: 女 | E26: 32 | F26: 未查 | G26: 1 | H26: 21 | I26: 15 | J26: c25 | L26: ctrl25
A27: 62 | B27: 20325884 | C27: 王水莲 | D27: 女 | E27: 48 | F27: 未查 | G27: 2.9 | H27: 16 | I27: 9 | J27: c26 | L27: ctrl26
A28: 65 | B28: 20380122 | C28: 刘康琪 | D28: 女 | E28: 23 | F28: 未查 | H28: 19 | I28: 12 | J28: c28 | L28: ctrl27
A29: 68 | B29: 20325470 | C29: 杨云飞 | D29: 女 | E29: 32 | F29: 未查 | G29: 6 | H29: 16 | I29: 9 | J29: c29 | L29: ctrl28
A30: 69 | B30: 20366409 | C30: 陈乃湘 | D30: 女 | E30: 81 | F30: 未查 | G30: 3 | H30: 29 | I30: 18 | J30: c30 | L30: ctrl29
A31: 73 | B31: 20286696 | C31: 张冉 | D31: 女 | E31: 32 | F31: 未查 | G31: 4 | J31: c31 | L31: ctrl30
A32: 74 | B32: 20366022 | C32: 陈善晓 | D32: 女 | E32: 45 | F32: 未查 | G32: 1.4 | H32: 18 | I32: 12 | J32: c32 | L32: ctrl31
A33: 79 | B33: 20379952 | C33: 杨梦姣 | D33: 女 | E33: 28 | F33: 未查 | G33: 1.4 | H33: 18 | I33: 13 | J33: c33 | L33: ctrl32
A34: 80 | B34: 20324994 | C34: 彭亚丽 | D34: 女 | E34: 51 | F34: 未查 | G34: 3 | H34: 27 | I34: 28 | J34: c34 | L34: ctrl33
A35: 81 | B35: 20325506 | C35: 朱雅萍 | D35: 女 | E35: 43 | F35: 未查 | G35: 2.2 | H35: 31 | I35: 51 | J35: c35 | L35: ctrl34
A36: 82 | B36: 20366043 | C36: 朱晓晖 | D36: 女 | E36: 57 | F36: 未查 | G36: 2.4 | H36: 23 | I36: 20 | J36: c36 | L36: ctrl35
A37: 83 | B37: 20379731 | C37: 梁倩艳 | D37: 女 | E37: 37 | F37: 未查 | G37: 3.9 | H37: 19 | I37: 16 | J37: c37 | L37: ctrl36
A38: 84 | B38: 20325655 | C38: 陈红叶 | D38: 女 | E38: 45 | F38: 未查 | G38: 3 | H38: 18 | I38: 12 | J38: c38 | L38: ctrl37
A39: 85 | B39: 20379677 | C39: 江悦 | D39: 女 | E39: 29 | F39: 未查 | G39: 1.3 | H39: 18 | I39: 12 | J39: c39 | L39: ctrl38
A40: 86 | B40: 20376082 | C40: 高燕铭 | D40: 女 | E40: 30 | F40: 未查 | G40: 4.3 | H40: 18 | I40: 11 | J40: c40 | L40: ctrl39
...

Sheet all
A1: sampleIm | B1: Age | C1: type | D1: 编号 | E1: batchIm | H1: sampleIm | I1: Age | J1: type | K1: 编号 | L1: batchIm
A2: ov1 | B2: 64 | C2: a | D2: B51 | E2: =VLOOKUP(A2,[1]batch_mesign!$J$1:$L$315,2,0) -> #N/A | H2: cys117 | I2: 24 | J2: cys | K2: a4 | L2: b1-1
A3: ov2 | B3: 71 | C3: a | D3: B2 | E3: =VLOOKUP(A3,batch_design!$J$1:$L$315,2,0) -> 71 | H3: ov103 | I3: 60 | J3: a | K3: B142 | L3: b1-2
A4: ov3 | B4: 56 | C4: a | D4: B12 | E4: =VLOOKUP(A4,batch_design!$J$1:$L$315,2,0) -> 56 | H4: ov98 | I4: 71 | J4: a | K4: B137 | L4: b1-3
A5: ov4 | B5: 49 | C5: a | D5: B3 | E5: =VLOOKUP(A5,batch_design!$J$1:$L$315,2,0) -> 49 | H5: ov11 | I5: 50 | J5: a | K5: B18 | L5: b1-4
A6: ov5 | B6: 18 | C6: g | D6: B5 | E6: =VLOOKUP(A6,batch_design!$J$1:$L$315,2,0) -> #N/A | H6: cys60 | I6: 36 | J6: cys | K6: a104 | L6: b1-5
A7: ov6 | B7: 48 | C7: m | D7: P6 | E7: =VLOOKUP(A7,batch_design!$J$1:$L$315,2,0) -> 48 | H7: cys106 | I7: 26 | J7: cys | K7: a109 | L7: b1-6
A8: ov7 | B8: 66 | C8: a | D8: P7 | E8: =VLOOKUP(A8,batch_design!$J$1:$L$315,2,0) -> 66 | H8: ov59 | I8: 41 | J8: m | K8: B80 | L8: b1-7
A9: ov8 | B9: 56 | C9: a | D9: B8 | E9: =VLOOKUP(A9,batch_design!$J$1:$L$315,2,0) -> 56 | H9: ov75 | I9: 51 | J9: b | K9: B105 | L9: b1-8
A10: ov9 | B10: 53 | C10: f | D10: B7 | E10: =VLOOKUP(A10,batch_design!$J$1:$L$315,2,0) -> 53 | H10: cys28 | I10: 45 | J10: cys | K10: a81 | L10: b1-9
A11: ov10 | B11: 50 | C11: a | D11: B15 | E11: =VLOOKUP(A11,batch_design!$J$1:$L$315,2,0) -> 50 | H11: cys69 | I11: 47 | J11: cys | K11: a145 | L11: b1-10
A12: ov11 | B12: 50 | C12: a | D12: B18 | E12: =VLOOKUP(A12,batch_design!$J$1:$L$315,2,0) -> 50 | H12: ctrl59 | I12: 57 | J12: ctrl | K12: c60 | L12: b1-11
A13: ov12 | B13: 61 | C13: a | D13: B20 | E13: =VLOOKUP(A13,batch_design!$J$1:$L$315,2,0) -> 61 | H13: cys64 | I13: 23 | J13: cys | K13: a135 | L13: b1-12
A14: ov13 | B14: 45 | C14: a | D14: B55 | E14: =VLOOKUP(A14,batch_design!$J$1:$L$315,2,0) -> 45 | H14: ctrl63 | I14: 46 | J14: ctrl | K14: c70 | L14: b1-13
... A315: ctrl70 | B315: 27 | C315: ctrl | D315: c92 | E315: =VLOOKUP(A315,batch_design!$J$1:$L$315,2,0) -> 27 | H315: ov69 | I315: 63 | J315: a | K315: B91 | L315: b23-13

Sheet batch_design
A1: sampleID | B1: Age | C1: type | D1: batch | E1: batchId | J1: sampleID | K1: Age | L1: batchId
A2: cys117 | B2: 24 | C2: cys | D2: 1 | E2: 1-1 | J2: cys117 | K2: 24 | L2: b1-1
A3: ov103 | B3: 60 | C3: a | D3: 1 | E3: 1-2 | J3: ov103 | K3: 60 | L3: b1-2 | M3: 溶血 | N3: b23-1
A4: ov98 | B4: 71 | C4: a | D4: 1 | E4: 1-3 | J4: ov98 | K4: 71 | L4: b1-3 | M4: 溶血 | N4: b23-2
A5: ov11 | B5: 50 | C5: a | D5: 1 | E5: 1-4 | J5: ov11 | K5: 50 | L5: b1-4
A6: cys60 | B6: 36 | C6: cys | D6: 1 | E6: 1-5 | J6: cys60 | K6: 36 | L6: b1-5
A7: cys106 | B7: 26 | C7: cys | D7: 1 | E7: 1-6 | J7: cys106 | K7: 26 | L7: b1-6
A8: ov59 | B8: 41 | C8: d | D8: 1 | E8: 1-7 | J8: ov59 | K8: 41 | L8: b1-7
A9: ov75 | B9: 51 | C9: b | D9: 1 | E9: 1-8 | J9: ov75 | K9: 51 | L9: b1-8
A10: cys28 | B10: 45 | C10: cys | D10: 1 | E10: 1-9 | J10: cys28 | K10: 45 | L10: b1-9
A11: cys69 | B11: 47 | C11: cys | D11: 1 | E11: 1-10 | J11: cys69 | K11: 47 | L11: b1-10
A12: ctrl59 | B12: 57 | C12: ctrl | D12: 1 | E12: 1-11 | J12: ctrl59 | K12: 57 | L12: b1-11
A13: cys64 | B13: 23 | C13: cys | D13: 1 | E13: 1-12 | J13: cys64 | K13: 23 | L13: b1-12
A14: ctrl63 | B14: 46 | C14: ctrl | D14: 1 | E14: 1-13 | J14: ctrl63 | K14: 46 | L14: b1-13
D15: 1 | E15: 1-14 | F15: bio-rep | N15: b23-5
A16: cys122 | B16: 30 | C16: cys | D16: 2 | E16: 2-1 | J16: cys122 | K16: 30 | L16: b2-1
A17: ctrl1 | B17: 43 | C17: ctrl | D17: 2 | E17: 2-2 | J17: ctrl1 | K17: 43 | L17: b2-2
A18: cys1 | B18: 57 | C18: cys | D18: 2 | E18: 2-3 | J18: cys1 | K18: 57 | L18: b2-3
A19: ctrl14 | B19: 33 | C19: ctrl | D19: 2 | E19: 2-4 | J19: ctrl14 | K19: 33 | L19: b2-4
A20: cys100 | B20: 27 | C20: cys | D20: 2 | E20: 2-5 | J20: cys100 | K20: 27 | L20: b2-5
A21: cys56 | B21: 46 | C21: cys | D21: 2 | E21: 2-6 | J21: cys56 | K21: 46 | L21: b2-6
A22: ctrl23 | B22: 22 | C22: ctrl | D22: 2 | E22: 2-7 | J22: ctrl23 | K22: 22 | L22: b2-7
A23: ctrl69 | B23: 46 | C23: ctrl | D23: 2 | E23: 2-8 | J23: ctrl69 | K23: 46 | L23: b2-8
A24: ov53 | B24: 40 | C24: j | D24: 2 | E24: 2-9 | J24: ov53 | K24: 40 | L24: b2-9
A25: cys8 | B25: 63 | C25: cys | D25: 2 | E25: 2-10 | J25: cys8 | K25: 63 | L25: b2-10
A26: ov48 | B26: 68 | C26: a | D26: 2 | E26: 2-11 | J26: ov48 | K26: 68 | L26: b2-11
A27: ctrl42 | B27: 40 | C27: ctrl | D27: 2 | E27: 2-12 | J27: ctrl42 | K27: 40 | L27: b2-12
... A35: cys13 | B35: 27 | C35: cys | D35: 3 | E35: 3-6 | J35: cys13 | K35: 27 | L35: b3-6
A36: ov71 | B36: 50 | C36: a | D36: 3 | E36: 3-7 | J36: ov71 | K36: 50 | L36: b3-7 | M36: 缺
A37: cys11 | B37: 33 | C37: cys | D37: 3 | E37: 3-8 | J37: cys11 | K37: 33 | L37: b3-8
A38: cys91 | B38: 37 | C38: cys | D38: 3 | E38: 3-9 | J38: cys91 | K38: 37 | L38: b3-9
A39: ov70 | B39: 31 | C39: c | D39: 3 | E39: 3-10 | J39: ov70 | K39: 31 | L39: b3-10 | M39: 溶血
A40: ov22 | B40: 51 | C40: a | D40: 3 | E40: 3-11 | J40: ov22 | K40: 51 | L40: b3-11
A41: cys88 | B41: 20 | C41: cys | D41: 3 | E41: 3-12 | J41: cys88 | K41: 20 | L41: b3-12
A42: ov104 | B42: 56 | C42: b | D42: 3 | E42: 3-13 | J42: ov104 | K42: 56 | L42: b3-13
E43: 3-14 | F43: bio-rep | N43: 23-6
A44: cys18 | B44: 44 | C44: cys | D44: 4 | E44: 4-1 | J44: cys18 | K44: 44 | L44: b4-1
A45: cys37 | B45: 33 | C45: cys | D45: 4 | E45: 4-2 | J45: cys37 | K45: 33 | L45: b4-2
A46: cys74 | B46: 31 | C46: cys | D46: 4 | E46: 4-3 | J46: cys74 | K46: 31 | L46: b4-3
A47: cys83 | B47: 41 | C47: cys | D47: 4 | E47: 4-4 | J47: cys83 | K47: 41 | L47: b4-4
...

Sheet 机器学习
A1: sampleID | B1: Age | C1: type | D1: batch | E1: batchId | J1: sampleIm | K1: Age | L1: batchId | O1: is_tech
A2: ctrl1 | B2: 43 | C2: ctrl | D2: 2 | E2: 2-2 | J2: ctrl1 | K2: 43 | L2: b2-2
A3: ctrl10 | B3: 23 | C3: ctrl | D3: 15 | E3: 15-4 | J3: ctrl10 | K3: 23 | L3: b15-4
A4: ctrl11 | B4: 25 | C4: ctrl | D4: 7 | E4: 7-10 | J4: ctrl11 | K4: 25 | L4: b7-10
A5: ctrl12 | B5: 31 | C5: ctrl | D5: 13 | E5: 13-4 | J5: ctrl12 | K5: 31 | L5: b13-4
A6: ctrl13 | B6: 51 | C6: ctrl | D6: 20 | E6: 20-13 | J6: ctrl13 | K6: 51 | L6: b20-13
A7: ctrl14 | B7: 33 | C7: ctrl | D7: 2 | E7: 2-4 | J7: ctrl14 | K7: 33 | L7: b2-4
A8: ctrl15 | B8: 40 | C8: ctrl | D8: 18 | E8: 18-11 | J8: ctrl15 | K8: 40 | L8: b18-11
A9: ctrl16 | B9: 49 | C9: ctrl | D9: 14 | E9: 14-7 | J9: ctrl16 | K9: 49 | L9: b14-7
A10: ctrl17 | B10: 45 | C10: ctrl | D10: 20 | E10: 20-9 | J10: ctrl17 | K10: 45 | L10: b20-9
A11: ctrl18 | B11: 28 | C11: ctrl | D11: 18 | E11: 18-4 | J11: ctrl18 | K11: 28 | L11: b18-4
A12: ctrl19 | B12: 28 | C12: ctrl | D12: 5 | E12: 5-9 | J12: ctrl19 | K12: 28 | L12: b5-9
A13: ctrl2 | B13: 27 | C13: ctrl | D13: 14 | E13: 14-2 | J13: ctrl2 | K13: 27 | L13: b14-2
... A28: ctrl33 | B28: 51 | C28: ctrl | D28: 16 | E28: 16-6 | J28: ctrl33 | K28: 51 | L28: b16-6
A29: ctrl33 | B29: 51 | C29: ctrl | D29: 16 | E29: 16-14 | J29: ctrl33 | K29: 51 | L29: b16-14 | M29: B16-6techrep | O29: 1
A30: ctrl34 | B30: 43 | C30: ctrl | D30: 9 | E30: 9-5 | J30: ctrl34 | K30: 43 | L30: b9-5
A31: ctrl35 | B31: 57 | C31: ctrl | D31: 11 | E31: 11-4 | J31: ctrl35 | K31: 57 | L31: b11-4
A32: ctrl36 | B32: 37 | C32: ctrl | D32: 11 | E32: 11-3 | J32: ctrl36 | K32: 37 | L32: b11-2
A33: ctrl37 | B33: 45 | C33: ctrl | D33: 22 | E33: 22-10 | J33: ctrl37 | K33: 45 | L33: b22-10
A34: ctrl38 | B34: 29 | C34: ctrl | D34: 17 | E34: 17-10 | J34: ctrl38 | K34: 29 | L34: b17-10
A35: ctrl39 | B35: 30 | C35: ctrl | D35: 5 | E35: 5-13 | J35: ctrl39 | K35: 30 | L35: b5-13
A36: ctrl4 | B36: 42 | C36: ctrl | D36: 21 | E36: 21-6 | J36: ctrl4 | K36: 42 | L36: b21-6
A37: ctrl40 | B37: 38 | C37: ctrl | D37: 1 | E37: 1-14 | J37: ctrl40 | K37: 38 | L37: b1-14
A38: ctrl41 | B38: 29 | C38: ctrl | D38: 3 | E38: 3-14 | J38: ctrl41 | K38: 29 | L38: b3-14
A39: ctrl42 | B39: 40 | C39: ctrl | D39: 2 | E39: 2-12 | J39: ctrl42 | K39: 40 | L39: b2-12
A40: ctrl43 | B40: 52 | C40: ctrl | D40: 8 | E40: 8-5 | J40: ctrl43 | K40: 52 | L40: b8-5
A41: ctrl44 | B41: 44 | C41: ctrl | D41: 19 | E41: 19-4 | J41: ctrl44 | K41: 44 | L41: b19-4
... A306: ov99 | B306: 51 | C306: a | D306: 10 | E306: 10-3 | J306: ov99 | K306: 51 | L306: b10-3
A307: ov64 | C307: c | E307: 7-14 | J307: ov64 | K307: 61 | L307: b7-14 | M307: b7-7techrep | O307: 1
A308: cys61 | C308: cys | J308: cys61 | K308: 47 | L308: b12-15 | M308: B12-1techrep | O308: 1
